
Epoch: [0]  [  0/455]  eta: 0:19:37  lr: 0.000001  loss: 7.9699 (7.9699)  loss_classifier: 1.3428 (1.3428)  loss_box_reg: 0.0032 (0.0032)  loss_objectness: 5.9984 (5.9984)  loss_rpn_box_reg: 0.6254 (0.6254)  time: 2.5890  data: 0.3542  max mem: 3016
Traceback (most recent call last):
  File "/home/irteam/junghye-dcloud-dir/pathfinder/pathfinder_ai/faster-rcnn/train.py", line 86, in <module>
    train_one_epoch(model, optimizer, train_dataloader, device, epoch, print_freq=10)
  File "/home/irteam/junghye-dcloud-dir/pathfinder/pathfinder_ai/faster-rcnn/engine.py", line 26, in train_one_epoch
    for images, targets in metric_logger.log_every(data_loader, print_freq, header):
  File "/home/irteam/junghye-dcloud-dir/pathfinder/pathfinder_ai/faster-rcnn/utils.py", line 201, in log_every
    for obj in iterable:
  File "/home/irteam/anaconda3/envs/pixt/lib/python3.10/site-packages/torch/utils/data/dataloader.py", line 633, in __next__
    data = self._next_data()
  File "/home/irteam/anaconda3/envs/pixt/lib/python3.10/site-packages/torch/utils/data/dataloader.py", line 1325, in _next_data
    return self._process_data(data)
  File "/home/irteam/anaconda3/envs/pixt/lib/python3.10/site-packages/torch/utils/data/dataloader.py", line 1371, in _process_data
    data.reraise()
  File "/home/irteam/anaconda3/envs/pixt/lib/python3.10/site-packages/torch/_utils.py", line 644, in reraise
    raise exception
TypeError: Caught TypeError in DataLoader worker process 3.
Original Traceback (most recent call last):
  File "/home/irteam/anaconda3/envs/pixt/lib/python3.10/site-packages/torch/utils/data/_utils/worker.py", line 308, in _worker_loop
    data = fetcher.fetch(index)
  File "/home/irteam/anaconda3/envs/pixt/lib/python3.10/site-packages/torch/utils/data/_utils/fetch.py", line 51, in fetch
    data = [self.dataset[idx] for idx in possibly_batched_index]
  File "/home/irteam/anaconda3/envs/pixt/lib/python3.10/site-packages/torch/utils/data/_utils/fetch.py", line 51, in <listcomp>
    data = [self.dataset[idx] for idx in possibly_batched_index]
  File "/home/irteam/junghye-dcloud-dir/pathfinder/pathfinder_ai/faster-rcnn/dataset.py", line 62, in __getitem__
    sample=self.transforms(image=image_res,
  File "/home/irteam/anaconda3/envs/pixt/lib/python3.10/site-packages/albumentations/core/composition.py", line 199, in __call__
    p.ensure_data_valid(data)
  File "/home/irteam/anaconda3/envs/pixt/lib/python3.10/site-packages/albumentations/core/bbox_utils.py", line 113, in ensure_data_valid
    if data_exists and len(data[data_name][0]) < 5:
  File "/home/irteam/anaconda3/envs/pixt/lib/python3.10/site-packages/torch/_tensor.py", line 908, in __len__
    raise TypeError("len() of a 0-d tensor")
TypeError: len() of a 0-d tensor