
Epoch: [0]  [  0/455]  eta: 0:20:34  lr: 0.000001  loss: 7.6550 (7.6550)  loss_classifier: 0.8903 (0.8903)  loss_box_reg: 0.0070 (0.0070)  loss_objectness: 6.3157 (6.3157)  loss_rpn_box_reg: 0.4421 (0.4421)  time: 2.7124  data: 0.3763  max mem: 3016
Epoch: [0]  [ 10/455]  eta: 0:05:01  lr: 0.000005  loss: 6.1592 (6.4533)  loss_classifier: 0.8863 (0.8829)  loss_box_reg: 0.0043 (0.0059)  loss_objectness: 4.9727 (5.1433)  loss_rpn_box_reg: 0.4363 (0.4212)  time: 0.6785  data: 0.0423  max mem: 3174
Traceback (most recent call last):
  File "/home/irteam/junghye-dcloud-dir/pathfinder/pathfinder_ai/faster-rcnn/train.py", line 86, in <module>
    train_one_epoch(model, optimizer, train_dataloader, device, epoch, print_freq=10)
  File "/home/irteam/junghye-dcloud-dir/pathfinder/pathfinder_ai/faster-rcnn/engine.py", line 26, in train_one_epoch
    for images, targets in metric_logger.log_every(data_loader, print_freq, header):
  File "/home/irteam/junghye-dcloud-dir/pathfinder/pathfinder_ai/faster-rcnn/utils.py", line 201, in log_every
    for obj in iterable:
  File "/home/irteam/anaconda3/envs/pixt/lib/python3.10/site-packages/torch/utils/data/dataloader.py", line 633, in __next__
    data = self._next_data()
  File "/home/irteam/anaconda3/envs/pixt/lib/python3.10/site-packages/torch/utils/data/dataloader.py", line 1345, in _next_data
    return self._process_data(data)
  File "/home/irteam/anaconda3/envs/pixt/lib/python3.10/site-packages/torch/utils/data/dataloader.py", line 1371, in _process_data
    data.reraise()
  File "/home/irteam/anaconda3/envs/pixt/lib/python3.10/site-packages/torch/_utils.py", line 644, in reraise
    raise exception
AssertionError: Caught AssertionError in DataLoader worker process 0.
Original Traceback (most recent call last):
  File "/home/irteam/anaconda3/envs/pixt/lib/python3.10/site-packages/torch/utils/data/_utils/worker.py", line 308, in _worker_loop
    data = fetcher.fetch(index)
  File "/home/irteam/anaconda3/envs/pixt/lib/python3.10/site-packages/torch/utils/data/_utils/fetch.py", line 51, in fetch
    data = [self.dataset[idx] for idx in possibly_batched_index]
  File "/home/irteam/anaconda3/envs/pixt/lib/python3.10/site-packages/torch/utils/data/_utils/fetch.py", line 51, in <listcomp>
    data = [self.dataset[idx] for idx in possibly_batched_index]
  File "/home/irteam/junghye-dcloud-dir/pathfinder/pathfinder_ai/faster-rcnn/dataset.py", line 62, in __getitem__
    sample=self.transforms(image=image_res,
  File "/home/irteam/anaconda3/envs/pixt/lib/python3.10/site-packages/albumentations/core/composition.py", line 207, in __call__
    p.preprocess(data)
  File "/home/irteam/anaconda3/envs/pixt/lib/python3.10/site-packages/albumentations/core/utils.py", line 79, in preprocess
    data = self.add_label_fields_to_data(data)
  File "/home/irteam/anaconda3/envs/pixt/lib/python3.10/site-packages/albumentations/core/utils.py", line 118, in add_label_fields_to_data
    assert len(data[data_name]) == len(data[field])
AssertionError